Workbook

Sheet SUMMARY
A1: ADS GY Equity — FY2016-FY2023 P&L Summary
A2: SYNTHETIC teaching data — not actual company results | EUR mn except per-share
A4: Total Net Revenue FY2023 | C4: ='MASTER P&L'!J8 -> 21427
A5: Revenue CAGR FY16-23 | C5: ='TREND & MARGIN ANALYSIS'!C11 -> 0.02133883
A6: Gross Margin FY2023 | C6: ='MASTER P&L'!J12 -> 0.475
A7: Operating Margin FY2023 | C7: ='MASTER P&L'!J22 -> 0.017
A8: Net Income Attrib. FY2023 | C8: ='MASTER P&L'!J32 -> -33
A9: Basic EPS FY2023 | C9: ='MASTER P&L'!J33 -> -0.18
A11: See MASTER P&L, TREND & MARGIN ANALYSIS and REGIONAL (RESTATED) tabs for full detail and charts.

Sheet MASTER P&L
A1: ADS GY Equity — Master P&L (EUR mn, except per-share data)
A2: SYNTHETIC teaching data — not actual company results. Built entirely with INDEX/MATCH lookups against the DATA sheet.
A4: Line Item | B4: Code | C4: 2016 | D4: 2017 | E4: 2018 | F4: 2019 | G4: 2020 | H4: 2021 | I4: 2022 | J4: 2023 | K4: Statement Group (lookup)
A5: Wholesale | B5: IS_REV_WS | C5: =IFERROR(INDEX(DATA!$D:$D,MATCH($B5&"|"&C$4,DATA!$H:$H,0)),"n/a") -> 11663 | D5: =IFERROR(INDEX(DATA!$D:$D,MATCH($B5&"|"&D$4,DATA!$H:$H,0)),"n/a") -> 12943 | E5: =IFERROR(INDEX(DATA!$D:$D,MATCH($B5&"|"&E$4,DATA!$H:$H,0)),"n/a") -> 12733 | F5: =IFERROR(INDEX(DATA!$D:$D,MATCH($B5&"|"&F$4,DATA!$H:$H,0)),"n/a") -> 13191 | G5: =IFERROR(INDEX(DATA!$D:$D,MATCH($B5&"|"&G$4,DATA!$H:$H,0)),"n/a") -> 10160 | H5: =IFERROR(INDEX(DATA!$D:$D,MATCH($B5&"|"&H$4,DATA!$H:$H,0)),"n/a") -> 11148 | I5: =IFERROR(INDEX(DATA!$D:$D,MATCH($B5&"|"&I$4,DATA!$H:$H,0)),"n/a") -> 12156 | J5: =IFERROR(INDEX(DATA!$D:$D,MATCH($B5&"|"&J$4,DATA!$H:$H,0)),"n/a") -> 11142 | K5: =IFERROR(INDEX('LOOKUP TABLES'!$C$3:$C$29,MATCH($B5,'LOOKUP TABLES'!$A$3:$A$29,0)),"Not in dictionary") -> Revenue
A6: Retail | B6: IS_REV_RT | C6: =IFERROR(INDEX(DATA!$D:$D,MATCH($B6&"|"&C$4,DATA!$H:$H,0)),"n/a") -> 5841 | D6: =IFERROR(INDEX(DATA!$D:$D,MATCH($B6&"|"&D$4,DATA!$H:$H,0)),"n/a") -> 7172 | E6: =IFERROR(INDEX(DATA!$D:$D,MATCH($B6&"|"&E$4,DATA!$H:$H,0)),"n/a") -> 8196 | F6: =IFERROR(INDEX(DATA!$D:$D,MATCH($B6&"|"&F$4,DATA!$H:$H,0)),"n/a") -> 9480 | G6: =IFERROR(INDEX(DATA!$D:$D,MATCH($B6&"|"&G$4,DATA!$H:$H,0)),"n/a") -> 8970 | H6: =IFERROR(INDEX(DATA!$D:$D,MATCH($B6&"|"&H$4,DATA!$H:$H,0)),"n/a") -> 9428 | I6: =IFERROR(INDEX(DATA!$D:$D,MATCH($B6&"|"&I$4,DATA!$H:$H,0)),"n/a") -> 9725 | J6: =IFERROR(INDEX(DATA!$D:$D,MATCH($B6&"|"&J$4,DATA!$H:$H,0)),"n/a") -> 9706 | K6: =IFERROR(INDEX('LOOKUP TABLES'!$C$3:$C$29,MATCH($B6,'LOOKUP TABLES'!$A$3:$A$29,0)),"Not in dictionary") -> Revenue
A7: Other Businesses | B7: IS_REV_OTH | C7: =IFERROR(INDEX(DATA!$D:$D,MATCH($B7&"|"&C$4,DATA!$H:$H,0)),"n/a") -> 979 | D7: =IFERROR(INDEX(DATA!$D:$D,MATCH($B7&"|"&D$4,DATA!$H:$H,0)),"n/a") -> 1103 | E7: =IFERROR(INDEX(DATA!$D:$D,MATCH($B7&"|"&E$4,DATA!$H:$H,0)),"n/a") -> 986 | F7: =IFERROR(INDEX(DATA!$D:$D,MATCH($B7&"|"&F$4,DATA!$H:$H,0)),"n/a") -> 969 | G7: =IFERROR(INDEX(DATA!$D:$D,MATCH($B7&"|"&G$4,DATA!$H:$H,0)),"n/a") -> 714 | H7: =IFERROR(INDEX(DATA!$D:$D,MATCH($B7&"|"&H$4,DATA!$H:$H,0)),"n/a") -> 658 | I7: =IFERROR(INDEX(DATA!$D:$D,MATCH($B7&"|"&I$4,DATA!$H:$H,0)),"n/a") -> 630 | J7: =IFERROR(INDEX(DATA!$D:$D,MATCH($B7&"|"&J$4,DATA!$H:$H,0)),"n/a") -> 579 | K7: =IFERROR(INDEX('LOOKUP TABLES'!$C$3:$C$29,MATCH($B7,'LOOKUP TABLES'!$A$3:$A$29,0)),"Not in dictionary") -> Revenue
A8: Total Net Revenue | B8: IS_REV_TOT | C8: =IFERROR(INDEX(DATA!$D:$D,MATCH($B8&"|"&C$4,DATA!$H:$H,0)),"n/a") -> 18483 | D8: =IFERROR(INDEX(DATA!$D:$D,MATCH($B8&"|"&D$4,DATA!$H:$H,0)),"n/a") -> 21218 | E8: =IFERROR(INDEX(DATA!$D:$D,MATCH($B8&"|"&E$4,DATA!$H:$H,0)),"n/a") -> 21915 | F8: =IFERROR(INDEX(DATA!$D:$D,MATCH($B8&"|"&F$4,DATA!$H:$H,0)),"n/a") -> 23640 | G8: =IFERROR(INDEX(DATA!$D:$D,MATCH($B8&"|"&G$4,DATA!$H:$H,0)),"n/a") -> 19844 | H8: =IFERROR(INDEX(DATA!$D:$D,MATCH($B8&"|"&H$4,DATA!$H:$H,0)),"n/a") -> 21234 | I8: =IFERROR(INDEX(DATA!$D:$D,MATCH($B8&"|"&I$4,DATA!$H:$H,0)),"n/a") -> 22511 | J8: =IFERROR(INDEX(DATA!$D:$D,MATCH($B8&"|"&J$4,DATA!$H:$H,0)),"n/a") -> 21427 | K8: =IFERROR(INDEX('LOOKUP TABLES'!$C$3:$C$29,MATCH($B8,'LOOKUP TABLES'!$A$3:$A$29,0)),"Not in dictionary") -> Revenue
A9: Revenue Growth Y/Y | B9: IS_REVGR | C9: =IFERROR(INDEX(DATA!$D:$D,MATCH($B9&"|"&C$4,DATA!$H:$H,0)),"n/a") -> 0 | D9: =IFERROR(INDEX(DATA!$D:$D,MATCH($B9&"|"&D$4,DATA!$H:$H,0)),"n/a") -> 0.148 | E9: =IFERROR(INDEX(DATA!$D:$D,MATCH($B9&"|"&E$4,DATA!$H:$H,0)),"n/a") -> 0.033 | F9: =IFERROR(INDEX(DATA!$D:$D,MATCH($B9&"|"&F$4,DATA!$H:$H,0)),"n/a") -> 0.079 | G9: =IFERROR(INDEX(DATA!$D:$D,MATCH($B9&"|"&G$4,DATA!$H:$H,0)),"n/a") -> -0.161 | H9: =IFERROR(INDEX(DATA!$D:$D,MATCH($B9&"|"&H$4,DATA!$H:$H,0)),"n/a") -> 0.07 | I9: =IFERROR(INDEX(DATA!$D:$D,MATCH($B9&"|"&I$4,DATA!$H:$H,0)),"n/a") -> 0.06 | J9: =IFERROR(INDEX(DATA!$D:$D,MATCH($B9&"|"&J$4,DATA!$H:$H,0)),"n/a") -> -0.048 | K9: =IFERROR(INDEX('LOOKUP TABLES'!$C$3:$C$29,MATCH($B9,'LOOKUP TABLES'!$A$3:$A$29,0)),"Not in dictionary") -> Not in dictionary
A10: Cost of Goods Sold | B10: IS_COGS | C10: =IFERROR(INDEX(DATA!$D:$D,MATCH($B10&"|"&C$4,DATA!$H:$H,0)),"n/a") -> -9500 | D10: =IFERROR(INDEX(DATA!$D:$D,MATCH($B10&"|"&D$4,DATA!$H:$H,0)),"n/a") -> -10524 | E10: =IFERROR(INDEX(DATA!$D:$D,MATCH($B10&"|"&E$4,DATA!$H:$H,0)),"n/a") -> -10607 | F10: =IFERROR(INDEX(DATA!$D:$D,MATCH($B10&"|"&F$4,DATA!$H:$H,0)),"n/a") -> -11347 | G10: =IFERROR(INDEX(DATA!$D:$D,MATCH($B10&"|"&G$4,DATA!$H:$H,0)),"n/a") -> -9982 | H10: =IFERROR(INDEX(DATA!$D:$D,MATCH($B10&"|"&H$4,DATA!$H:$H,0)),"n/a") -> -10511 | I10: =IFERROR(INDEX(DATA!$D:$D,MATCH($B10&"|"&I$4,DATA!$H:$H,0)),"n/a") -> -11863 | J10: =IFERROR(INDEX(DATA!$D:$D,MATCH($B10&"|"&J$4,DATA!$H:$H,0)),"n/a") -> -11249 | K10: =IFERROR(INDEX('LOOKUP TABLES'!$C$3:$C$29,MATCH($B10,'LOOKUP TABLES'!$A$3:$A$29,0)),"Not in dictionary") -> Cost
A11: Gross Profit | B11: IS_GP | C11: =IFERROR(INDEX(DATA!$D:$D,MATCH($B11&"|"&C$4,DATA!$H:$H,0)),"n/a") -> 8983 | D11: =IFERROR(INDEX(DATA!$D:$D,MATCH($B11&"|"&D$4,DATA!$H:$H,0)),"n/a") -> 10694 | E11: =IFERROR(INDEX(DATA!$D:$D,MATCH($B11&"|"&E$4,DATA!$H:$H,0)),"n/a") -> 11308 | F11: =IFERROR(INDEX(DATA!$D:$D,MATCH($B11&"|"&F$4,DATA!$H:$H,0)),"n/a") -> 12293 | G11: =IFERROR(INDEX(DATA!$D:$D,MATCH($B11&"|"&G$4,DATA!$H:$H,0)),"n/a") -> 9862 | H11: =IFERROR(INDEX(DATA!$D:$D,MATCH($B11&"|"&H$4,DATA!$H:$H,0)),"n/a") -> 10723 | I11: =IFERROR(INDEX(DATA!$D:$D,MATCH($B11&"|"&I$4,DATA!$H:$H,0)),"n/a") -> 10648 | J11: =IFERROR(INDEX(DATA!$D:$D,MATCH($B11&"|"&J$4,DATA!$H:$H,0)),"n/a") -> 10178 | K11: =IFERROR(INDEX('LOOKUP TABLES'!$C$3:$C$29,MATCH($B11,'LOOKUP TABLES'!$A$3:$A$29,0)),"Not in dictionary") -> Subtotal
A12: Gross Margin % | B12: IS_GPM | C12: =IFERROR(INDEX(DATA!$D:$D,MATCH($B12&"|"&C$4,DATA!$H:$H,0)),"n/a") -> 0.486 | D12: =IFERROR(INDEX(DATA!$D:$D,MATCH($B12&"|"&D$4,DATA!$H:$H,0)),"n/a") -> 0.504 | E12: =IFERROR(INDEX(DATA!$D:$D,MATCH($B12&"|"&E$4,DATA!$H:$H,0)),"n/a") -> 0.516 | F12: =IFERROR(INDEX(DATA!$D:$D,MATCH($B12&"|"&F$4,DATA!$H:$H,0)),"n/a") -> 0.52 | G12: =IFERROR(INDEX(DATA!$D:$D,MATCH($B12&"|"&G$4,DATA!$H:$H,0)),"n/a") -> 0.497 | H12: =IFERROR(INDEX(DATA!$D:$D,MATCH($B12&"|"&H$4,DATA!$H:$H,0)),"n/a") -> 0.505 | I12: =IFERROR(INDEX(DATA!$D:$D,MATCH($B12&"|"&I$4,DATA!$H:$H,0)),"n/a") -> 0.473 | J12: =IFERROR(INDEX(DATA!$D:$D,MATCH($B12&"|"&J$4,DATA!$H:$H,0)),"n/a") -> 0.475 | K12: =IFERROR(INDEX('LOOKUP TABLES'!$C$3:$C$29,MATCH($B12,'LOOKUP TABLES'!$A$3:$A$29,0)),"Not in dictionary") -> Not in dictionary
A13: Royalty and Commission Income | B13: IS_ROY | C13: =IFERROR(INDEX(DATA!$D:$D,MATCH($B13&"|"&C$4,DATA!$H:$H,0)),"n/a") -> 108 | D13: =IFERROR(INDEX(DATA!$D:$D,MATCH($B13&"|"&D$4,DATA!$H:$H,0)),"n/a") -> 115 | E13: =IFERROR(INDEX(DATA!$D:$D,MATCH($B13&"|"&E$4,DATA!$H:$H,0)),"n/a") -> 121 | F13: =IFERROR(INDEX(DATA!$D:$D,MATCH($B13&"|"&F$4,DATA!$H:$H,0)),"n/a") -> 130 | G13: =IFERROR(INDEX(DATA!$D:$D,MATCH($B13&"|"&G$4,DATA!$H:$H,0)),"n/a") -> 96 | H13: =IFERROR(INDEX(DATA!$D:$D,MATCH($B13&"|"&H$4,DATA!$H:$H,0)),"n/a") -> 104 | I13: =IFERROR(INDEX(DATA!$D:$D,MATCH($B13&"|"&I$4,DATA!$H:$H,0)),"n/a") -> 112 | J13: =IFERROR(INDEX(DATA!$D:$D,MATCH($B13&"|"&J$4,DATA!$H:$H,0)),"n/a") -> 107 | K13: =IFERROR(INDEX('LOOKUP TABLES'!$C$3:$C$29,MATCH($B13,'LOOKUP TABLES'!$A$3:$A$29,0)),"Not in dictionary") -> Other income
A14: Other Operating Income | B14: IS_OOI | C14: =IFERROR(INDEX(DATA!$D:$D,MATCH($B14&"|"&C$4,DATA!$H:$H,0)),"n/a") -> 60 | D14: =IFERROR(INDEX(DATA!$D:$D,MATCH($B14&"|"&D$4,DATA!$H:$H,0)),"n/a") -> 66 | E14: =IFERROR(INDEX(DATA!$D:$D,MATCH($B14&"|"&E$4,DATA!$H:$H,0)),"n/a") -> 71 | F14: =IFERROR(INDEX(DATA!$D:$D,MATCH($B14&"|"&F$4,DATA!$H:$H,0)),"n/a") -> 78 | G14: =IFERROR(INDEX(DATA!$D:$D,MATCH($B14&"|"&G$4,DATA!$H:$H,0)),"n/a") -> 52 | H14: =IFERROR(INDEX(DATA!$D:$D,MATCH($B14&"|"&H$4,DATA!$H:$H,0)),"n/a") -> 58 | I14: =IFERROR(INDEX(DATA!$D:$D,MATCH($B14&"|"&I$4,DATA!$H:$H,0)),"n/a") -> 63 | J14: =IFERROR(INDEX(DATA!$D:$D,MATCH($B14&"|"&J$4,DATA!$H:$H,0)),"n/a") -> 55 | K14: =IFERROR(INDEX('LOOKUP TABLES'!$C$3:$C$29,MATCH($B14,'LOOKUP TABLES'!$A$3:$A$29,0)),"Not in dictionary") -> Other income
A15: Marketing and Point-of-Sale | B15: IS_MKT | C15: =IFERROR(INDEX(DATA!$D:$D,MATCH($B15&"|"&C$4,DATA!$H:$H,0)),"n/a") -> -2532 | D15: =IFERROR(INDEX(DATA!$D:$D,MATCH($B15&"|"&D$4,DATA!$H:$H,0)),"n/a") -> -2843 | E15: =IFERROR(INDEX(DATA!$D:$D,MATCH($B15&"|"&E$4,DATA!$H:$H,0)),"n/a") -> -2871 | F15: =IFERROR(INDEX(DATA!$D:$D,MATCH($B15&"|"&F$4,DATA!$H:$H,0)),"n/a") -> -3026 | G15: =IFERROR(INDEX(DATA!$D:$D,MATCH($B15&"|"&G$4,DATA!$H:$H,0)),"n/a") -> -2361 | H15: =IFERROR(INDEX(DATA!$D:$D,MATCH($B15&"|"&H$4,DATA!$H:$H,0)),"n/a") -> -2569 | I15: =IFERROR(INDEX(DATA!$D:$D,MATCH($B15&"|"&I$4,DATA!$H:$H,0)),"n/a") -> -2791 | J15: =IFERROR(INDEX(DATA!$D:$D,MATCH($B15&"|"&J$4,DATA!$H:$H,0)),"n/a") -> -2636 | K15: =IFERROR(INDEX('LOOKUP TABLES'!$C$3:$C$29,MATCH($B15,'LOOKUP TABLES'!$A$3:$A$29,0)),"Not in dictionary") -> Operating expense
A16: Distribution and Selling Expense | B16: IS_DIST | C16: =IFERROR(INDEX(DATA!$D:$D,MATCH($B16&"|"&C$4,DATA!$H:$H,0)),"n/a") -> -4029 | D16: =IFERROR(INDEX(DATA!$D:$D,MATCH($B16&"|"&D$4,DATA!$H:$H,0)),"n/a") -> -4710 | E16: =IFERROR(INDEX(DATA!$D:$D,MATCH($B16&"|"&E$4,DATA!$H:$H,0)),"n/a") -> -4909 | F16: =IFERROR(INDEX(DATA!$D:$D,MATCH($B16&"|"&F$4,DATA!$H:$H,0)),"n/a") -> -5272 | G16: =IFERROR(INDEX(DATA!$D:$D,MATCH($B16&"|"&G$4,DATA!$H:$H,0)),"n/a") -> -5358 | H16: =IFERROR(INDEX(DATA!$D:$D,MATCH($B16&"|"&H$4,DATA!$H:$H,0)),"n/a") -> -4969 | I16: =IFERROR(INDEX(DATA!$D:$D,MATCH($B16&"|"&I$4,DATA!$H:$H,0)),"n/a") -> -5470 | J16: =IFERROR(INDEX(DATA!$D:$D,MATCH($B16&"|"&J$4,DATA!$H:$H,0)),"n/a") -> -5528 | K16: =IFERROR(INDEX('LOOKUP TABLES'!$C$3:$C$29,MATCH($B16,'LOOKUP TABLES'!$A$3:$A$29,0)),"Not in dictionary") -> Operating expense
... A39: Segment Reallocation (code not in dictionary) | B39: IS_SEGRE | C39: =IFERROR(INDEX(DATA!$D:$D,MATCH($B39&"|"&C$4,DATA!$H:$H,0)),"n/a") -> n/a | D39: =IFERROR(INDEX(DATA!$D:$D,MATCH($B39&"|"&D$4,DATA!$H:$H,0)),"n/a") -> n/a | E39: =IFERROR(INDEX(DATA!$D:$D,MATCH($B39&"|"&E$4,DATA!$H:$H,0)),"n/a") -> n/a | F39: =IFERROR(INDEX(DATA!$D:$D,MATCH($B39&"|"&F$4,DATA!$H:$H,0)),"n/a") -> n/a | G39: =IFERROR(INDEX(DATA!$D:$D,MATCH($B39&"|"&G$4,DATA!$H:$H,0)),"n/a") -> n/a | H39: =IFERROR(INDEX(DATA!$D:$D,MATCH($B39&"|"&H$4,DATA!$H:$H,0)),"n/a") -> n/a | I39: =IFERROR(INDEX(DATA!$D:$D,MATCH($B39&"|"&I$4,DATA!$H:$H,0)),"n/a") -> n/a | J39: =IFERROR(INDEX(DATA!$D:$D,MATCH($B39&"|"&J$4,DATA!$H:$H,0)),"n/a") -> n/a | K39: =IFERROR(INDEX('LOOKUP TABLES'!$C$3:$C$29,MATCH($B39,'LOOKUP TABLES'!$A$3:$A$29,0)),"Not in dictionary") -> Not in dictionary

Sheet TREND & MARGIN ANALYSIS
A1: Trend & Profitability Analysis (all formulas reference MASTER P&L — nothing pasted)
A3: Metric | C3: 2016 | D3: 2017 | E3: 2018 | F3: 2019 | G3: 2020 | H3: 2021 | I3: 2022 | J3: 2023
A4: YoY Growth
A5: Revenue Growth % | D5: =IFERROR('MASTER P&L'!D8/'MASTER P&L'!C8-1,"n/a") -> 0.14797381 | E5: =IFERROR('MASTER P&L'!E8/'MASTER P&L'!D8-1,"n/a") -> 0.032849467 | F5: =IFERROR('MASTER P&L'!F8/'MASTER P&L'!E8-1,"n/a") -> 0.07871321 | G5: =IFERROR('MASTER P&L'!G8/'MASTER P&L'!F8-1,"n/a") -> -0.1605753 | H5: =IFERROR('MASTER P&L'!H8/'MASTER P&L'!G8-1,"n/a") -> 0.070046362 | I5: =IFERROR('MASTER P&L'!I8/'MASTER P&L'!H8-1,"n/a") -> 0.060139399 | J5: =IFERROR('MASTER P&L'!J8/'MASTER P&L'!I8-1,"n/a") -> -0.048154236
A6: Gross Profit Growth % | D6: =IFERROR('MASTER P&L'!D11/'MASTER P&L'!C11-1,"n/a") -> 0.19047089 | E6: =IFERROR('MASTER P&L'!E11/'MASTER P&L'!D11-1,"n/a") -> 0.057415373 | F6: =IFERROR('MASTER P&L'!F11/'MASTER P&L'!E11-1,"n/a") -> 0.087106473 | G6: =IFERROR('MASTER P&L'!G11/'MASTER P&L'!F11-1,"n/a") -> -0.19775482 | H6: =IFERROR('MASTER P&L'!H11/'MASTER P&L'!G11-1,"n/a") -> 0.087304806 | I6: =IFERROR('MASTER P&L'!I11/'MASTER P&L'!H11-1,"n/a") -> -0.0069943113 | J6: =IFERROR('MASTER P&L'!J11/'MASTER P&L'!I11-1,"n/a") -> -0.044139745
A7: Operating Profit Growth % | D7: =IFERROR('MASTER P&L'!D21/'MASTER P&L'!C21-1,"n/a") -> 0.41080313 | E7: =IFERROR('MASTER P&L'!E21/'MASTER P&L'!D21-1,"n/a") -> 0.18942065 | F7: =IFERROR('MASTER P&L'!F21/'MASTER P&L'!E21-1,"n/a") -> 0.10969928 | G7: =IFERROR('MASTER P&L'!G21/'MASTER P&L'!F21-1,"n/a") -> -0.69351145 | H7: =IFERROR('MASTER P&L'!H21/'MASTER P&L'!G21-1,"n/a") -> 1.2914072 | I7: =IFERROR('MASTER P&L'!I21/'MASTER P&L'!H21-1,"n/a") -> -0.78967391 | J7: =IFERROR('MASTER P&L'!J21/'MASTER P&L'!I21-1,"n/a") -> -0.082687339
A8: Net Income Growth % | D8: =IFERROR('MASTER P&L'!D32/'MASTER P&L'!C32-1,"n/a") -> 0.44678609 | E8: =IFERROR('MASTER P&L'!E32/'MASTER P&L'!D32-1,"n/a") -> 0.23088128 | F8: =IFERROR('MASTER P&L'!F32/'MASTER P&L'!E32-1,"n/a") -> 0.097633136 | G8: =IFERROR('MASTER P&L'!G32/'MASTER P&L'!F32-1,"n/a") -> -0.81293801 | H8: =IFERROR('MASTER P&L'!H32/'MASTER P&L'!G32-1,"n/a") -> 3.1700288 | I8: =IFERROR('MASTER P&L'!I32/'MASTER P&L'!H32-1,"n/a") -> -0.96544575 | J8: =IFERROR('MASTER P&L'!J32/'MASTER P&L'!I32-1,"n/a") -> -1.66
A10: FY2016-FY2023 CAGR
A11: Revenue CAGR | C11: =('MASTER P&L'!J8/'MASTER P&L'!C8)^(1/7)-1 -> 0.02133883
A12: Net Income CAGR | C12: =('MASTER P&L'!J32/'MASTER P&L'!C32)^(1/7)-1 -> -1.6188805
A15: Indexed Series (FY2016 = 100)
C16: 2016 | D16: 2017 | E16: 2018 | F16: 2019 | G16: 2020 | H16: 2021 | I16: 2022 | J16: 2023
A17: Revenue (Index) | C17: =ABS('MASTER P&L'!C8)/ABS('MASTER P&L'!$C$8)*100 -> 100 | D17: =ABS('MASTER P&L'!D8)/ABS('MASTER P&L'!$C$8)*100 -> 114.79738 | E17: =ABS('MASTER P&L'!E8)/ABS('MASTER P&L'!$C$8)*100 -> 118.56841 | F17: =ABS('MASTER P&L'!F8)/ABS('MASTER P&L'!$C$8)*100 -> 127.90131 | G17: =ABS('MASTER P&L'!G8)/ABS('MASTER P&L'!$C$8)*100 -> 107.36352 | H17: =ABS('MASTER P&L'!H8)/ABS('MASTER P&L'!$C$8)*100 -> 114.88395 | I17: =ABS('MASTER P&L'!I8)/ABS('MASTER P&L'!$C$8)*100 -> 121.793 | J17: =ABS('MASTER P&L'!J8)/ABS('MASTER P&L'!$C$8)*100 -> 115.92815
A18: Gross Profit (Index) | C18: =ABS('MASTER P&L'!C11)/ABS('MASTER P&L'!$C$11)*100 -> 100 | D18: =ABS('MASTER P&L'!D11)/ABS('MASTER P&L'!$C$11)*100 -> 119.04709 | E18: =ABS('MASTER P&L'!E11)/ABS('MASTER P&L'!$C$11)*100 -> 125.88222 | F18: =ABS('MASTER P&L'!F11)/ABS('MASTER P&L'!$C$11)*100 -> 136.84738 | G18: =ABS('MASTER P&L'!G11)/ABS('MASTER P&L'!$C$11)*100 -> 109.78515 | H18: =ABS('MASTER P&L'!H11)/ABS('MASTER P&L'!$C$11)*100 -> 119.36992 | I18: =ABS('MASTER P&L'!I11)/ABS('MASTER P&L'!$C$11)*100 -> 118.53501 | J18: =ABS('MASTER P&L'!J11)/ABS('MASTER P&L'!$C$11)*100 -> 113.30291
A19: Total Opex (Index) | C19: =ABS('MASTER P&L'!C19)/ABS('MASTER P&L'!$C$19)*100 -> 100 | D19: =ABS('MASTER P&L'!D19)/ABS('MASTER P&L'!$C$19)*100 -> 114.79855 | E19: =ABS('MASTER P&L'!E19)/ABS('MASTER P&L'!$C$19)*100 -> 118.01395 | F19: =ABS('MASTER P&L'!F19)/ABS('MASTER P&L'!$C$19)*100 -> 127.59556 | G19: =ABS('MASTER P&L'!G19)/ABS('MASTER P&L'!$C$19)*100 -> 118.89205 | H19: =ABS('MASTER P&L'!H19)/ABS('MASTER P&L'!$C$19)*100 -> 116.8001 | I19: =ABS('MASTER P&L'!I19)/ABS('MASTER P&L'!$C$19)*100 -> 132.25723 | J19: =ABS('MASTER P&L'!J19)/ABS('MASTER P&L'!$C$19)*100 -> 128.93853
A21: Margin Trio
C22: 2016 | D22: 2017 | E22: 2018 | F22: 2019 | G22: 2020 | H22: 2021 | I22: 2022 | J22: 2023
A23: Gross Margin % | C23: ='MASTER P&L'!C12 -> 0.486 | D23: ='MASTER P&L'!D12 -> 0.504 | E23: ='MASTER P&L'!E12 -> 0.516 | F23: ='MASTER P&L'!F12 -> 0.52 | G23: ='MASTER P&L'!G12 -> 0.497 | H23: ='MASTER P&L'!H12 -> 0.505 | I23: ='MASTER P&L'!I12 -> 0.473 | J23: ='MASTER P&L'!J12 -> 0.475
A24: Operating Margin % | C24: ='MASTER P&L'!C22 -> 0.076 | D24: ='MASTER P&L'!D22 -> 0.094 | E24: ='MASTER P&L'!E22 -> 0.108 | F24: ='MASTER P&L'!F22 -> 0.111 | G24: ='MASTER P&L'!G22 -> 0.04 | H24: ='MASTER P&L'!H22 -> 0.087 | I24: ='MASTER P&L'!I22 -> 0.017 | J24: ='MASTER P&L'!J22 -> 0.017
A25: Net Margin % | C25: =IFERROR('MASTER P&L'!C32/'MASTER P&L'!C8,"n/a") -> 0.051344479 | D25: =IFERROR('MASTER P&L'!D32/'MASTER P&L'!D8,"n/a") -> 0.064709209 | E25: =IFERROR('MASTER P&L'!E32/'MASTER P&L'!E8,"n/a") -> 0.077116131 | F25: =IFERROR('MASTER P&L'!F32/'MASTER P&L'!F8,"n/a") -> 0.078468697 | G25: =IFERROR('MASTER P&L'!G32/'MASTER P&L'!G8,"n/a") -> 0.017486394 | H25: =IFERROR('MASTER P&L'!H32/'MASTER P&L'!H8,"n/a") -> 0.068145427 | I25: =IFERROR('MASTER P&L'!I32/'MASTER P&L'!I8,"n/a") -> 0.0022211363 | J25: =IFERROR('MASTER P&L'!J32/'MASTER P&L'!J8,"n/a") -> -0.0015401129
A27: Operating Expenses as % of Net Sales
C28: 2016 | D28: 2017 | E28: 2018 | F28: 2019 | G28: 2020 | H28: 2021 | I28: 2022 | J28: 2023
A29: Marketing & POS % Sales | C29: =ABS('MASTER P&L'!C15)/'MASTER P&L'!C8 -> 0.13699075 | D29: =ABS('MASTER P&L'!D15)/'MASTER P&L'!D8 -> 0.13399001 | E29: =ABS('MASTER P&L'!E15)/'MASTER P&L'!E8 -> 0.13100616 | F29: =ABS('MASTER P&L'!F15)/'MASTER P&L'!F8 -> 0.12800338 | G29: =ABS('MASTER P&L'!G15)/'MASTER P&L'!G8 -> 0.11897803 | H29: =ABS('MASTER P&L'!H15)/'MASTER P&L'!H8 -> 0.12098521 | I29: =ABS('MASTER P&L'!I15)/'MASTER P&L'!I8 -> 0.12398383 | J29: =ABS('MASTER P&L'!J15)/'MASTER P&L'!J8 -> 0.12302235
A30: Distribution & Selling % Sales | C30: =ABS('MASTER P&L'!C16)/'MASTER P&L'!C8 -> 0.21798409 | D30: =ABS('MASTER P&L'!D16)/'MASTER P&L'!D8 -> 0.22198134 | E30: =ABS('MASTER P&L'!E16)/'MASTER P&L'!E8 -> 0.22400183 | F30: =ABS('MASTER P&L'!F16)/'MASTER P&L'!F8 -> 0.22301184 | G30: =ABS('MASTER P&L'!G16)/'MASTER P&L'!G8 -> 0.27000605 | H30: =ABS('MASTER P&L'!H16)/'MASTER P&L'!H8 -> 0.23401149 | I30: =ABS('MASTER P&L'!I16)/'MASTER P&L'!I8 -> 0.24299231 | J30: =ABS('MASTER P&L'!J16)/'MASTER P&L'!J8 -> 0.25799225
A31: G&A % Sales | C31: =ABS('MASTER P&L'!C17)/'MASTER P&L'!C8 -> 0.053995563 | D31: =ABS('MASTER P&L'!D17)/'MASTER P&L'!D8 -> 0.05302102 | E31: =ABS('MASTER P&L'!E17)/'MASTER P&L'!E8 -> 0.052019165 | F31: =ABS('MASTER P&L'!F17)/'MASTER P&L'!F8 -> 0.056979695 | G31: =ABS('MASTER P&L'!G17)/'MASTER P&L'!G8 -> 0.065007055 | H31: =ABS('MASTER P&L'!H17)/'MASTER P&L'!H8 -> 0.060987096 | I31: =ABS('MASTER P&L'!I17)/'MASTER P&L'!I8 -> 0.078006308 | J31: =ABS('MASTER P&L'!J17)/'MASTER P&L'!J8 -> 0.072992019
A32: Sundry % Sales | C32: =ABS('MASTER P&L'!C18)/'MASTER P&L'!C8 -> 0.010009198 | D32: =ABS('MASTER P&L'!D18)/'MASTER P&L'!D8 -> 0.0099915166 | E32: =ABS('MASTER P&L'!E18)/'MASTER P&L'!E8 -> 0.0099931554 | F32: =ABS('MASTER P&L'!F18)/'MASTER P&L'!F8 -> 0.0099830795 | G32: =ABS('MASTER P&L'!G18)/'MASTER P&L'!G8 -> 0.0099778271 | H32: =ABS('MASTER P&L'!H18)/'MASTER P&L'!H8 -> 0.0099839879 | I32: =ABS('MASTER P&L'!I18)/'MASTER P&L'!I8 -> 0.0099951135 | J32: =ABS('MASTER P&L'!J18)/'MASTER P&L'!J8 -> 0.011994213
A34: Effective Tax Rate %
C35: =IFERROR(-'MASTER P&L'!C26/'MASTER P&L'!C25,"n/a") -> 0.28972653 | D35: =IFERROR(-'MASTER P&L'!D26/'MASTER P&L'!D25,"n/a") -> 0.28022833 | E35: =IFERROR(-'MASTER P&L'!E26/'MASTER P&L'!E25,"n/a") -> 0.25979112 | F35: =IFERROR(-'MASTER P&L'!F26/'MASTER P&L'!F25,"n/a") -> 0.25020113 | G35: =IFERROR(-'MASTER P&L'!G26/'MASTER P&L'!G25,"n/a") -> 0.35023041 | H35: =IFERROR(-'MASTER P&L'!H26/'MASTER P&L'!H25,"n/a") -> 0.27974087 | I35: =IFERROR(-'MASTER P&L'!I26/'MASTER P&L'!I25,"n/a") -> 0.75 | J35: =IFERROR(-'MASTER P&L'!J26/'MASTER P&L'!J25,"n/a") -> 1.1485714

Sheet REGIONAL (RESTATED)
A1: Regional Revenue — Comparable Basis (EUR mn), mapped via LOOKUP TABLES Table 2
A3: SOURCE: as reported (two regimes)
A4: Reported Region | B4: 2016 | C4: 2017 | D4: 2018 | E4: 2019 | F4: 2020 | G4: 2021 | H4: 2022 | I4: 2023
A5: Western Europe | B5: 5452 | C5: 5856 | D5: 5764 | E5: 5957
A6: North America (pre) | B6: 3068 | C6: 3947 | D6: 4361 | E6: 4917
A7: Greater China (pre) | B7: 2976 | C7: 3756 | D7: 4164 | E7: 4728
A8: Russia/CIS | B8: 721 | C8: 700 | D8: 679 | E8: 686
A9: Latin America (pre) | B9: 1645 | C9: 1740 | D9: 1688 | E9: 1726
A10: Other Asian Markets | B10: 2421 | C10: 2716 | D10: 2761 | E10: 2931
A11: Emerging Markets | B11: 1220 | C11: 1400 | D11: 1512 | E11: 1726
A12: Other Businesses (pre) | B12: 980 | C12: 1103 | D12: 986 | E12: 969
A13: EMEA | F13: 7005 | G13: 7432 | H13: 7879 | I13: 7585
A14: North America (post) | F14: 4127 | G14: 5330 | H14: 5921 | I14: 5142
A15: Greater China (post) | F15: 4346 | G15: 4247 | H15: 3534 | I15: 3257
A16: Asia-Pacific | F16: 2342 | G16: 2060 | H16: 2656 | I16: 2807
A17: Latin America (post) | F17: 1310 | G17: 1507 | H17: 1891 | I17: 2057
A18: Other Businesses (post) | F18: 714 | G18: 658 | H18: 630 | I18: 579
A20: COMPARABLE VIEW: Reporting Cluster (mapped, all 8 years)
A21: Reporting Cluster | B21: 2016 | C21: 2017 | D21: 2018 | E21: 2019 | F21: 2020 | G21: 2021 | H21: 2022 | I21: 2023
A22: EMEA | B22: =SUM(B5,B8,B11,B13) -> 7393 | C22: =SUM(C5,C8,C11,C13) -> 7956 | D22: =SUM(D5,D8,D11,D13) -> 7955 | E22: =SUM(E5,E8,E11,E13) -> 8369 | F22: =SUM(F5,F8,F11,F13) -> 7005 | G22: =SUM(G5,G8,G11,G13) -> 7432 | H22: =SUM(H5,H8,H11,H13) -> 7879 | I22: =SUM(I5,I8,I11,I13) -> 7585
A23: North America | B23: =SUM(B6,B14) -> 3068 | C23: =SUM(C6,C14) -> 3947 | D23: =SUM(D6,D14) -> 4361 | E23: =SUM(E6,E14) -> 4917 | F23: =SUM(F6,F14) -> 4127 | G23: =SUM(G6,G14) -> 5330 | H23: =SUM(H6,H14) -> 5921 | I23: =SUM(I6,I14) -> 5142
A24: Greater China | B24: =SUM(B7,B15) -> 2976 | C24: =SUM(C7,C15) -> 3756 | D24: =SUM(D7,D15) -> 4164 | E24: =SUM(E7,E15) -> 4728 | F24: =SUM(F7,F15) -> 4346 | G24: =SUM(G7,G15) -> 4247 | H24: =SUM(H7,H15) -> 3534 | I24: =SUM(I7,I15) -> 3257
A25: Asia-Pacific | B25: =SUM(B10,B16) -> 2421 | C25: =SUM(C10,C16) -> 2716 | D25: =SUM(D10,D16) -> 2761 | E25: =SUM(E10,E16) -> 2931 | F25: =SUM(F10,F16) -> 2342 | G25: =SUM(G10,G16) -> 2060 | H25: =SUM(H10,H16) -> 2656 | I25: =SUM(I10,I16) -> 2807
A26: Latin America | B26: =SUM(B9,B17) -> 1645 | C26: =SUM(C9,C17) -> 1740 | D26: =SUM(D9,D17) -> 1688 | E26: =SUM(E9,E17) -> 1726 | F26: =SUM(F9,F17) -> 1310 | G26: =SUM(G9,G17) -> 1507 | H26: =SUM(H9,H17) -> 1891 | I26: =SUM(I9,I17) -> 2057
A27: Other Businesses | B27: =SUM(B12,B18) -> 980 | C27: =SUM(C12,C18) -> 1103 | D27: =SUM(D12,D18) -> 986 | E27: =SUM(E12,E18) -> 969 | F27: =SUM(F12,F18) -> 714 | G27: =SUM(G12,G18) -> 658 | H27: =SUM(H12,H18) -> 630 | I27: =SUM(I12,I18) -> 579
A28: Total | B28: =SUM(B22:B27) -> 18483 | C28: =SUM(C22:C27) -> 21218 | D28: =SUM(D22:D27) -> 21915 | E28: =SUM(E22:E27) -> 23640 | F28: =SUM(F22:F27) -> 19844 | G28: =SUM(G22:G27) -> 21234 | H28: =SUM(H22:H27) -> 22511 | I28: =SUM(I22:I27) -> 21427
A30: Note: pre-FY2020 and post-FY2020 region names differ (Bloomberg restated segmentation FY2020). This view maps both regimes onto one set of 6 comparable clusters using the region-mapping table on LOOKUP TABLES. It supports a like-for-like 8-year regional trend; it cannot support claims about the exact pre-2020 country mix within EMEA, since Western Europe / Russia-CIS / Emerging Markets are now combined.

Sheet DATA
A1: code | B1: line_item | C1: fiscal_year | D1: value | E1: statement_group | F1: is_subtotal | G1: is_percent_metric | H1: lookup_key
A2: IS_COGS | B2: Cost of Goods Sold | C2: 2016 | D2: -9500 | E2: Cost | F2: =FALSE() -> FALSE | G2: =FALSE() -> FALSE | H2: IS_COGS|2016
A3: IS_COGS | B3: Cost of Goods Sold | C3: 2017 | D3: -10524 | E3: Cost | F3: =FALSE() -> FALSE | G3: =FALSE() -> FALSE | H3: IS_COGS|2017
A4: IS_COGS | B4: Cost of Goods Sold | C4: 2018 | D4: -10607 | E4: Cost | F4: =FALSE() -> FALSE | G4: =FALSE() -> FALSE | H4: IS_COGS|2018
A5: IS_COGS | B5: Cost of Goods Sold | C5: 2019 | D5: -11347 | E5: Cost | F5: =FALSE() -> FALSE | G5: =FALSE() -> FALSE | H5: IS_COGS|2019
A6: IS_COGS | B6: Cost of Goods Sold | C6: 2020 | D6: -9982 | E6: Cost | F6: =FALSE() -> FALSE | G6: =FALSE() -> FALSE | H6: IS_COGS|2020
A7: IS_COGS | B7: Cost of Goods Sold | C7: 2021 | D7: -10511 | E7: Cost | F7: =FALSE() -> FALSE | G7: =FALSE() -> FALSE | H7: IS_COGS|2021
A8: IS_COGS | B8: Cost of Goods Sold | C8: 2022 | D8: -11863 | E8: Cost | F8: =FALSE() -> FALSE | G8: =FALSE() -> FALSE | H8: IS_COGS|2022
A9: IS_COGS | B9: Cost of Goods Sold | C9: 2023 | D9: -11249 | E9: Cost | F9: =FALSE() -> FALSE | G9: =FALSE() -> FALSE | H9: IS_COGS|2023
A10: IS_DIST | B10: Distribution and Selling Expense | C10: 2016 | D10: -4029 | E10: Operating expense | F10: =FALSE() -> FALSE | G10: =FALSE() -> FALSE | H10: IS_DIST|2016
A11: IS_DIST | B11: Distribution and Selling Expense | C11: 2017 | D11: -4710 | E11: Operating expense | F11: =FALSE() -> FALSE | G11: =FALSE() -> FALSE | H11: IS_DIST|2017
A12: IS_DIST | B12: Distribution and Selling Expense | C12: 2018 | D12: -4909 | E12: Operating expense | F12: =FALSE() -> FALSE | G12: =FALSE() -> FALSE | H12: IS_DIST|2018
A13: IS_DIST | B13: Distribution and Selling Expense | C13: 2019 | D13: -5272 | E13: Operating expense | F13: =FALSE() -> FALSE | G13: =FALSE() -> FALSE | H13: IS_DIST|2019
... A21: IS_DPS | B21: Dividend Per Share (DPS) | C21: 2019 | D21: 3.85 | E21: Per share | F21: =FALSE() -> FALSE | G21: =FALSE() -> FALSE | H21: IS_DPS|2019
A22: IS_DPS | B22: Dividend Per Share (DPS) | C22: 2020 | E22: Per share | F22: =FALSE() -> FALSE | G22: =FALSE() -> FALSE | H22: IS_DPS|2020
A23: IS_DPS | B23: Dividend Per Share (DPS) | C23: 2021 | D23: 3.3 | E23: Per share | F23: =FALSE() -> FALSE | G23: =FALSE() -> FALSE | H23: IS_DPS|2021
A24: IS_DPS | B24: Dividend Per Share (DPS) | C24: 2022 | D24: 0.7 | E24: Per share | F24: =FALSE() -> FALSE | G24: =FALSE() -> FALSE | H24: IS_DPS|2022
A25: IS_DPS | B25: Dividend Per Share (DPS) | C25: 2023 | D25: 0.7 | E25: Per share | F25: =FALSE() -> FALSE | G25: =FALSE() -> FALSE | H25: IS_DPS|2023
A26: IS_EBIT | B26: Operating Profit (EBIT) | C26: 2016 | D26: 1407 | E26: Subtotal | F26: =TRUE() -> TRUE | G26: =FALSE() -> FALSE | H26: IS_EBIT|2016
A27: IS_EBIT | B27: Operating Profit (EBIT) | C27: 2017 | D27: 1985 | E27: Subtotal | F27: =TRUE() -> TRUE | G27: =FALSE() -> FALSE | H27: IS_EBIT|2017
A28: IS_EBIT | B28: Operating Profit (EBIT) | C28: 2018 | D28: 2361 | E28: Subtotal | F28: =TRUE() -> TRUE | G28: =FALSE() -> FALSE | H28: IS_EBIT|2018
A29: IS_EBIT | B29: Operating Profit (EBIT) | C29: 2019 | D29: 2620 | E29: Subtotal | F29: =TRUE() -> TRUE | G29: =FALSE() -> FALSE | H29: IS_EBIT|2019
A30: IS_EBIT | B30: Operating Profit (EBIT) | C30: 2020 | D30: 803 | E30: Subtotal | F30: =TRUE() -> TRUE | G30: =FALSE() -> FALSE | H30: IS_EBIT|2020
A31: IS_EBIT | B31: Operating Profit (EBIT) | C31: 2021 | D31: 1840 | E31: Subtotal | F31: =TRUE() -> TRUE | G31: =FALSE() -> FALSE | H31: IS_EBIT|2021
A32: IS_EBIT | B32: Operating Profit (EBIT) | C32: 2022 | D32: 387 | E32: Subtotal | F32: =TRUE() -> TRUE | G32: =FALSE() -> FALSE | H32: IS_EBIT|2022
A33: IS_EBIT | B33: Operating Profit (EBIT) | C33: 2023 | D33: 355 | E33: Subtotal | F33: =TRUE() -> TRUE | G33: =FALSE() -> FALSE | H33: IS_EBIT|2023
A34: IS_EBT | B34: Income Before Taxes | C34: 2016 | D34: 1353 | E34: Subtotal | F34: =TRUE() -> TRUE | G34: =FALSE() -> FALSE | H34: IS_EBT|2016
A35: IS_EBT | B35: Income Before Taxes | C35: 2017 | D35: 1927 | E35: Subtotal | F35: =TRUE() -> TRUE | G35: =FALSE() -> FALSE | H35: IS_EBT|2017
A36: IS_EBT | B36: Income Before Taxes | C36: 2018 | D36: 2298 | E36: Subtotal | F36: =TRUE() -> TRUE | G36: =FALSE() -> FALSE | H36: IS_EBT|2018
A37: IS_EBT | B37: Income Before Taxes | C37: 2019 | D37: 2486 | E37: Subtotal | F37: =TRUE() -> TRUE | G37: =FALSE() -> FALSE | H37: IS_EBT|2019
... A41: IS_EBT | B41: Income Before Taxes | C41: 2023 | D41: 175 | E41: Subtotal | F41: =TRUE() -> TRUE | G41: =FALSE() -> FALSE | H41: IS_EBT|2023
A42: IS_EPSB | B42: Basic EPS | C42: 2016 | D42: 4.72 | E42: Per share | F42: =FALSE() -> FALSE | G42: =FALSE() -> FALSE | H42: IS_EPSB|2016
A43: IS_EPSB | B43: Basic EPS | C43: 2017 | D43: 6.78 | E43: Per share | F43: =FALSE() -> FALSE | G43: =FALSE() -> FALSE | H43: IS_EPSB|2017
A44: IS_EPSB | B44: Basic EPS | C44: 2018 | D44: 8.45 | E44: Per share | F44: =FALSE() -> FALSE | G44: =FALSE() -> FALSE | H44: IS_EPSB|2018
A45: IS_EPSB | B45: Basic EPS | C45: 2019 | D45: 9.48 | E45: Per share | F45: =FALSE() -> FALSE | G45: =FALSE() -> FALSE | H45: IS_EPSB|2019
A46: IS_EPSB | B46: Basic EPS | C46: 2020 | D46: 1.79 | E46: Per share | F46: =FALSE() -> FALSE | G46: =FALSE() -> FALSE | H46: IS_EPSB|2020
A47: IS_EPSB | B47: Basic EPS | C47: 2021 | D47: 7.39 | E47: Per share | F47: =FALSE() -> FALSE | G47: =FALSE() -> FALSE | H47: IS_EPSB|2021
A48: IS_EPSB | B48: Basic EPS | C48: 2022 | D48: 0.27 | E48: Per share | F48: =FALSE() -> FALSE | G48: =FALSE() -> FALSE | H48: IS_EPSB|2022
A49: IS_EPSB | B49: Basic EPS | C49: 2023 | D49: -0.18 | E49: Per share | F49: =FALSE() -> FALSE | G49: =FALSE() -> FALSE | H49: IS_EPSB|2023
A50: IS_EPSD | B50: Diluted EPS | C50: 2016 | D50: 4.7 | E50: Per share | F50: =FALSE() -> FALSE | G50: =FALSE() -> FALSE | H50: IS_EPSD|2016
...

Sheet LOOKUP TABLES
A1: TABLE 1 - Line item dictionary
A3: Line Item Code | B3: Line Item Description | C3: Statement Group | D3: Sign Convention
A4: IS_REV_WS | B4: Wholesale | C4: Revenue | D4: Positive
A5: IS_REV_RT | B5: Retail | C5: Revenue | D5: Positive
A6: IS_REV_OTH | B6: Other Businesses | C6: Revenue | D6: Positive
A7: IS_REV_TOT | B7: Total Net Revenue | C7: Revenue | D7: Positive
A8: IS_COGS | B8: Cost of Goods Sold | C8: Cost | D8: Negative
A9: IS_GP | B9: Gross Profit | C9: Subtotal | D9: Positive
A10: IS_ROY | B10: Royalty and Commission Income | C10: Other income | D10: Positive
A11: IS_OOI | B11: Other Operating Income | C11: Other income | D11: Positive
A12: IS_MKT | B12: Marketing and Point-of-Sale | C12: Operating expense | D12: Negative
A13: IS_DIST | B13: Distribution and Selling Expense | C13: Operating expense | D13: Negative
A14: IS_GNA | B14: General & Administration | C14: Operating expense | D14: Negative
... A30: IS_DPS | B30: Dividend Per Share (DPS) | C30: Per share | D30: Positive
A31: TABLE 2 - Regional segmentation mapping
A32: Reported Region (pre-FY2020) | B32: Reporting Cluster (FY2020 onward) | C32: Comparable?
A33: Western Europe | B33: EMEA | C33: Mapped
A34: Russia/CIS | B34: EMEA | C34: Mapped
A35: Emerging Markets | B35: EMEA | C35: Mapped
A36: North America | B36: North America | C36: Yes
A37: Greater China | B37: Greater China | C37: Yes
A38: Other Asian Markets | B38: Asia-Pacific | C38: Mapped
A39: Latin America | B39: Latin America | C39: Yes
A40: Other Businesses | B40: Other Businesses | C40: Yes
